Workbook

Sheet SOB126
A1: Z | B1: symbol | C1: name | D1: N_sob | E1: A_sob | F1: observed_isotope | G1: N_observed | H1: A_observed | I1: delta_N | J1: delta_A | K1: lambda_gcd | L1: primitive_Z | M1: primitive_N | N1: primitive_lane | O1: lane_ratio_NmZ_over_A | P1: chi | Q1: p_count | R1: n_count | S1: e_count | T1: u_count | U1: d_count | V1: Q_sub | W1: Q_mass | X1: delta_Q | Y1: channel_role | Z1: B_u_u | AA1: B_u_MeV | AB1: B_smooth_MeV | AC1: binding_residual_MeV | AD1: clock_role | AE1: row_status | AF1: notes
A2: 1 | B2: H | C2: Hydrogen | D2: =A2 + INT(A2 * INT((A2-1)/12) / 12) | E2: =A2+D2 | F2: =VLOOKUP(A2, Observed_Lookup!A:G, 4, FALSE) | G2: =VLOOKUP(A2, Observed_Lookup!A:G, 5, FALSE) | H2: =VLOOKUP(A2, Observed_Lookup!A:G, 6, FALSE) | I2: =IF(F2="","",D2-G2) | J2: =IF(F2="","",E2-H2) | K2: =GCD(A2,D2) | L2: =A2/K2 | M2: =D2/K2 | N2: ="("&L2&","&M2&")" | O2: =(D2-A2)/E2 | P2: =V2/W2 | Q2: =A2 | R2: =D2 | S2: =A2 | T2: =2*A2+D2 | U2: =A2+2*D2 | V2: =8*(A2*(7117/768)+(D2-A2)*(1/64)) | W2: =4*E2*(7117/768) | X2: =W2-V2 | Y2: =IF(P2<1,"substrate-light / mass-heavy",IF(P2>1,"substrate-heavy / mass-light","balanced")) | Z2: =IF(F2="","",H2-IFERROR(VLOOKUP(A2, Observed_Lookup!A:G, 7, FALSE),"")) | AA2: =IF(Z2="","",Z2*931.49410242) | AB2: =8*(A2+IF(F2="",D2,G2))-17*(A2+IF(F2="",D2,G2))^(2/3)-(3/4)*A2*(A2-1)/(A2+IF(F2="",D2,G2))^(1/3)-22*(IF(F2="",D2,G2)-A2)^2/(A2+IF(F2="",D2,G2))+7*IF(AND(MOD(A2,2)=0,MOD(IF(F2="",D2,G2),2)=0),1,IF(AND(MOD(A2,2)=1,MOD(IF(F2="",D2,G2),2)=1),-1,0))/SQRT((A2+IF(F2="",D2,G2)))-(25/4)*IF(AND((A2/GCD(A2,IF(F2="",D2,G2)))=1,(IF(F2="",D2,G2)/GCD(A2,IF(F2="",D2,G2)))=1),0,1) | AC2: =IF(AA2="","",AA2-AB2) | AD2: =IF(AND(A2<=83,A2<>43,A2<>61),"clock-stable","clock-boundary") | AE2: engine_diff_from_observed | AF2: engine anchor H-2 differs from observed most-abundant H-1
A3: 2 | B3: He | C3: Helium | D3: =A3 + INT(A3 * INT((A3-1)/12) / 12) | E3: =A3+D3 | F3: =VLOOKUP(A3, Observed_Lookup!A:G, 4, FALSE) | G3: =VLOOKUP(A3, Observed_Lookup!A:G, 5, FALSE) | H3: =VLOOKUP(A3, Observed_Lookup!A:G, 6, FALSE) | I3: =IF(F3="","",D3-G3) | J3: =IF(F3="","",E3-H3) | K3: =GCD(A3,D3) | L3: =A3/K3 | M3: =D3/K3 | N3: ="("&L3&","&M3&")" | O3: =(D3-A3)/E3 | P3: =V3/W3 | Q3: =A3 | R3: =D3 | S3: =A3 | T3: =2*A3+D3 | U3: =A3+2*D3 | V3: =8*(A3*(7117/768)+(D3-A3)*(1/64)) | W3: =4*E3*(7117/768) | X3: =W3-V3 | Y3: =IF(P3<1,"substrate-light / mass-heavy",IF(P3>1,"substrate-heavy / mass-light","balanced")) | Z3: =IF(F3="","",H3-IFERROR(VLOOKUP(A3, Observed_Lookup!A:G, 7, FALSE),"")) | AA3: =IF(Z3="","",Z3*931.49410242) | AB3: =8*(A3+IF(F3="",D3,G3))-17*(A3+IF(F3="",D3,G3))^(2/3)-(3/4)*A3*(A3-1)/(A3+IF(F3="",D3,G3))^(1/3)-22*(IF(F3="",D3,G3)-A3)^2/(A3+IF(F3="",D3,G3))+7*IF(AND(MOD(A3,2)=0,MOD(IF(F3="",D3,G3),2)=0),1,IF(AND(MOD(A3,2)=1,MOD(IF(F3="",D3,G3),2)=1),-1,0))/SQRT((A3+IF(F3="",D3,G3)))-(25/4)*IF(AND((A3/GCD(A3,IF(F3="",D3,G3)))=1,(IF(F3="",D3,G3)/GCD(A3,IF(F3="",D3,G3)))=1),0,1) | AC3: =IF(AA3="","",AA3-AB3) | AD3: =IF(AND(A3<=83,A3<>43,A3<>61),"clock-stable","clock-boundary") | AE3: engine_matches_observed
A4: 3 | B4: Li | C4: Lithium | D4: =A4 + INT(A4 * INT((A4-1)/12) / 12) | E4: =A4+D4 | F4: =VLOOKUP(A4, Observed_Lookup!A:G, 4, FALSE) | G4: =VLOOKUP(A4, Observed_Lookup!A:G, 5, FALSE) | H4: =VLOOKUP(A4, Observed_Lookup!A:G, 6, FALSE) | I4: =IF(F4="","",D4-G4) | J4: =IF(F4="","",E4-H4) | K4: =GCD(A4,D4) | L4: =A4/K4 | M4: =D4/K4 | N4: ="("&L4&","&M4&")" | O4: =(D4-A4)/E4 | P4: =V4/W4 | Q4: =A4 | R4: =D4 | S4: =A4 | T4: =2*A4+D4 | U4: =A4+2*D4 | V4: =8*(A4*(7117/768)+(D4-A4)*(1/64)) | W4: =4*E4*(7117/768) | X4: =W4-V4 | Y4: =IF(P4<1,"substrate-light / mass-heavy",IF(P4>1,"substrate-heavy / mass-light","balanced")) | Z4: =IF(F4="","",H4-IFERROR(VLOOKUP(A4, Observed_Lookup!A:G, 7, FALSE),"")) | AA4: =IF(Z4="","",Z4*931.49410242) | AB4: =8*(A4+IF(F4="",D4,G4))-17*(A4+IF(F4="",D4,G4))^(2/3)-(3/4)*A4*(A4-1)/(A4+IF(F4="",D4,G4))^(1/3)-22*(IF(F4="",D4,G4)-A4)^2/(A4+IF(F4="",D4,G4))+7*IF(AND(MOD(A4,2)=0,MOD(IF(F4="",D4,G4),2)=0),1,IF(AND(MOD(A4,2)=1,MOD(IF(F4="",D4,G4),2)=1),-1,0))/SQRT((A4+IF(F4="",D4,G4)))-(25/4)*IF(AND((A4/GCD(A4,IF(F4="",D4,G4)))=1,(IF(F4="",D4,G4)/GCD(A4,IF(F4="",D4,G4)))=1),0,1) | AC4: =IF(AA4="","",AA4-AB4) | AD4: =IF(AND(A4<=83,A4<>43,A4<>61),"clock-stable","clock-boundary") | AE4: engine_diff_from_observed | AF4: engine anchor Li-6 differs from observed most-abundant Li-7
A5: 4 | B5: Be | C5: Beryllium | D5: =A5 + INT(A5 * INT((A5-1)/12) / 12) | E5: =A5+D5 | F5: =VLOOKUP(A5, Observed_Lookup!A:G, 4, FALSE) | G5: =VLOOKUP(A5, Observed_Lookup!A:G, 5, FALSE) | H5: =VLOOKUP(A5, Observed_Lookup!A:G, 6, FALSE) | I5: =IF(F5="","",D5-G5) | J5: =IF(F5="","",E5-H5) | K5: =GCD(A5,D5) | L5: =A5/K5 | M5: =D5/K5 | N5: ="("&L5&","&M5&")" | O5: =(D5-A5)/E5 | P5: =V5/W5 | Q5: =A5 | R5: =D5 | S5: =A5 | T5: =2*A5+D5 | U5: =A5+2*D5 | V5: =8*(A5*(7117/768)+(D5-A5)*(1/64)) | W5: =4*E5*(7117/768) | X5: =W5-V5 | Y5: =IF(P5<1,"substrate-light / mass-heavy",IF(P5>1,"substrate-heavy / mass-light","balanced")) | Z5: =IF(F5="","",H5-IFERROR(VLOOKUP(A5, Observed_Lookup!A:G, 7, FALSE),"")) | AA5: =IF(Z5="","",Z5*931.49410242) | AB5: =8*(A5+IF(F5="",D5,G5))-17*(A5+IF(F5="",D5,G5))^(2/3)-(3/4)*A5*(A5-1)/(A5+IF(F5="",D5,G5))^(1/3)-22*(IF(F5="",D5,G5)-A5)^2/(A5+IF(F5="",D5,G5))+7*IF(AND(MOD(A5,2)=0,MOD(IF(F5="",D5,G5),2)=0),1,IF(AND(MOD(A5,2)=1,MOD(IF(F5="",D5,G5),2)=1),-1,0))/SQRT((A5+IF(F5="",D5,G5)))-(25/4)*IF(AND((A5/GCD(A5,IF(F5="",D5,G5)))=1,(IF(F5="",D5,G5)/GCD(A5,IF(F5="",D5,G5)))=1),0,1) | AC5: =IF(AA5="","",AA5-AB5) | AD5: =IF(AND(A5<=83,A5<>43,A5<>61),"clock-stable","clock-boundary") | AE5: engine_matches_observed
A6: 5 | B6: B | C6: Boron | D6: =A6 + INT(A6 * INT((A6-1)/12) / 12) | E6: =A6+D6 | F6: =VLOOKUP(A6, Observed_Lookup!A:G, 4, FALSE) | G6: =VLOOKUP(A6, Observed_Lookup!A:G, 5, FALSE) | H6: =VLOOKUP(A6, Observed_Lookup!A:G, 6, FALSE) | I6: =IF(F6="","",D6-G6) | J6: =IF(F6="","",E6-H6) | K6: =GCD(A6,D6) | L6: =A6/K6 | M6: =D6/K6 | N6: ="("&L6&","&M6&")" | O6: =(D6-A6)/E6 | P6: =V6/W6 | Q6: =A6 | R6: =D6 | S6: =A6 | T6: =2*A6+D6 | U6: =A6+2*D6 | V6: =8*(A6*(7117/768)+(D6-A6)*(1/64)) | W6: =4*E6*(7117/768) | X6: =W6-V6 | Y6: =IF(P6<1,"substrate-light / mass-heavy",IF(P6>1,"substrate-heavy / mass-light","balanced")) | Z6: =IF(F6="","",H6-IFERROR(VLOOKUP(A6, Observed_Lookup!A:G, 7, FALSE),"")) | AA6: =IF(Z6="","",Z6*931.49410242) | AB6: =8*(A6+IF(F6="",D6,G6))-17*(A6+IF(F6="",D6,G6))^(2/3)-(3/4)*A6*(A6-1)/(A6+IF(F6="",D6,G6))^(1/3)-22*(IF(F6="",D6,G6)-A6)^2/(A6+IF(F6="",D6,G6))+7*IF(AND(MOD(A6,2)=0,MOD(IF(F6="",D6,G6),2)=0),1,IF(AND(MOD(A6,2)=1,MOD(IF(F6="",D6,G6),2)=1),-1,0))/SQRT((A6+IF(F6="",D6,G6)))-(25/4)*IF(AND((A6/GCD(A6,IF(F6="",D6,G6)))=1,(IF(F6="",D6,G6)/GCD(A6,IF(F6="",D6,G6)))=1),0,1) | AC6: =IF(AA6="","",AA6-AB6) | AD6: =IF(AND(A6<=83,A6<>43,A6<>61),"clock-stable","clock-boundary") | AE6: engine_matches_observed
A7: 6 | B7: C | C7: Carbon | D7: =A7 + INT(A7 * INT((A7-1)/12) / 12) | E7: =A7+D7 | F7: =VLOOKUP(A7, Observed_Lookup!A:G, 4, FALSE) | G7: =VLOOKUP(A7, Observed_Lookup!A:G, 5, FALSE) | H7: =VLOOKUP(A7, Observed_Lookup!A:G, 6, FALSE) | I7: =IF(F7="","",D7-G7) | J7: =IF(F7="","",E7-H7) | K7: =GCD(A7,D7) | L7: =A7/K7 | M7: =D7/K7 | N7: ="("&L7&","&M7&")" | O7: =(D7-A7)/E7 | P7: =V7/W7 | Q7: =A7 | R7: =D7 | S7: =A7 | T7: =2*A7+D7 | U7: =A7+2*D7 | V7: =8*(A7*(7117/768)+(D7-A7)*(1/64)) | W7: =4*E7*(7117/768) | X7: =W7-V7 | Y7: =IF(P7<1,"substrate-light / mass-heavy",IF(P7>1,"substrate-heavy / mass-light","balanced")) | Z7: =IF(F7="","",H7-IFERROR(VLOOKUP(A7, Observed_Lookup!A:G, 7, FALSE),"")) | AA7: =IF(Z7="","",Z7*931.49410242) | AB7: =8*(A7+IF(F7="",D7,G7))-17*(A7+IF(F7="",D7,G7))^(2/3)-(3/4)*A7*(A7-1)/(A7+IF(F7="",D7,G7))^(1/3)-22*(IF(F7="",D7,G7)-A7)^2/(A7+IF(F7="",D7,G7))+7*IF(AND(MOD(A7,2)=0,MOD(IF(F7="",D7,G7),2)=0),1,IF(AND(MOD(A7,2)=1,MOD(IF(F7="",D7,G7),2)=1),-1,0))/SQRT((A7+IF(F7="",D7,G7)))-(25/4)*IF(AND((A7/GCD(A7,IF(F7="",D7,G7)))=1,(IF(F7="",D7,G7)/GCD(A7,IF(F7="",D7,G7)))=1),0,1) | AC7: =IF(AA7="","",AA7-AB7) | AD7: =IF(AND(A7<=83,A7<>43,A7<>61),"clock-stable","clock-boundary") | AE7: engine_diff_from_observed | AF7: engine anchor C-14 differs from observed most-abundant C-12
A8: 7 | B8: N | C8: Nitrogen | D8: =A8 + INT(A8 * INT((A8-1)/12) / 12) | E8: =A8+D8 | F8: =VLOOKUP(A8, Observed_Lookup!A:G, 4, FALSE) | G8: =VLOOKUP(A8, Observed_Lookup!A:G, 5, FALSE) | H8: =VLOOKUP(A8, Observed_Lookup!A:G, 6, FALSE) | I8: =IF(F8="","",D8-G8) | J8: =IF(F8="","",E8-H8) | K8: =GCD(A8,D8) | L8: =A8/K8 | M8: =D8/K8 | N8: ="("&L8&","&M8&")" | O8: =(D8-A8)/E8 | P8: =V8/W8 | Q8: =A8 | R8: =D8 | S8: =A8 | T8: =2*A8+D8 | U8: =A8+2*D8 | V8: =8*(A8*(7117/768)+(D8-A8)*(1/64)) | W8: =4*E8*(7117/768) | X8: =W8-V8 | Y8: =IF(P8<1,"substrate-light / mass-heavy",IF(P8>1,"substrate-heavy / mass-light","balanced")) | Z8: =IF(F8="","",H8-IFERROR(VLOOKUP(A8, Observed_Lookup!A:G, 7, FALSE),"")) | AA8: =IF(Z8="","",Z8*931.49410242) | AB8: =8*(A8+IF(F8="",D8,G8))-17*(A8+IF(F8="",D8,G8))^(2/3)-(3/4)*A8*(A8-1)/(A8+IF(F8="",D8,G8))^(1/3)-22*(IF(F8="",D8,G8)-A8)^2/(A8+IF(F8="",D8,G8))+7*IF(AND(MOD(A8,2)=0,MOD(IF(F8="",D8,G8),2)=0),1,IF(AND(MOD(A8,2)=1,MOD(IF(F8="",D8,G8),2)=1),-1,0))/SQRT((A8+IF(F8="",D8,G8)))-(25/4)*IF(AND((A8/GCD(A8,IF(F8="",D8,G8)))=1,(IF(F8="",D8,G8)/GCD(A8,IF(F8="",D8,G8)))=1),0,1) | AC8: =IF(AA8="","",AA8-AB8) | AD8: =IF(AND(A8<=83,A8<>43,A8<>61),"clock-stable","clock-boundary") | AE8: engine_diff_from_observed | AF8: engine anchor N-17 differs from observed most-abundant N-14
A9: 8 | B9: O | C9: Oxygen | D9: =A9 + INT(A9 * INT((A9-1)/12) / 12) | E9: =A9+D9 | F9: =VLOOKUP(A9, Observed_Lookup!A:G, 4, FALSE) | G9: =VLOOKUP(A9, Observed_Lookup!A:G, 5, FALSE) | H9: =VLOOKUP(A9, Observed_Lookup!A:G, 6, FALSE) | I9: =IF(F9="","",D9-G9) | J9: =IF(F9="","",E9-H9) | K9: =GCD(A9,D9) | L9: =A9/K9 | M9: =D9/K9 | N9: ="("&L9&","&M9&")" | O9: =(D9-A9)/E9 | P9: =V9/W9 | Q9: =A9 | R9: =D9 | S9: =A9 | T9: =2*A9+D9 | U9: =A9+2*D9 | V9: =8*(A9*(7117/768)+(D9-A9)*(1/64)) | W9: =4*E9*(7117/768) | X9: =W9-V9 | Y9: =IF(P9<1,"substrate-light / mass-heavy",IF(P9>1,"substrate-heavy / mass-light","balanced")) | Z9: =IF(F9="","",H9-IFERROR(VLOOKUP(A9, Observed_Lookup!A:G, 7, FALSE),"")) | AA9: =IF(Z9="","",Z9*931.49410242) | AB9: =8*(A9+IF(F9="",D9,G9))-17*(A9+IF(F9="",D9,G9))^(2/3)-(3/4)*A9*(A9-1)/(A9+IF(F9="",D9,G9))^(1/3)-22*(IF(F9="",D9,G9)-A9)^2/(A9+IF(F9="",D9,G9))+7*IF(AND(MOD(A9,2)=0,MOD(IF(F9="",D9,G9),2)=0),1,IF(AND(MOD(A9,2)=1,MOD(IF(F9="",D9,G9),2)=1),-1,0))/SQRT((A9+IF(F9="",D9,G9)))-(25/4)*IF(AND((A9/GCD(A9,IF(F9="",D9,G9)))=1,(IF(F9="",D9,G9)/GCD(A9,IF(F9="",D9,G9)))=1),0,1) | AC9: =IF(AA9="","",AA9-AB9) | AD9: =IF(AND(A9<=83,A9<>43,A9<>61),"clock-stable","clock-boundary") | AE9: engine_diff_from_observed | AF9: engine anchor O-20 differs from observed most-abundant O-16
A10: 9 | B10: F | C10: Fluorine | D10: =A10 + INT(A10 * INT((A10-1)/12) / 12) | E10: =A10+D10 | F10: =VLOOKUP(A10, Observed_Lookup!A:G, 4, FALSE) | G10: =VLOOKUP(A10, Observed_Lookup!A:G, 5, FALSE) | H10: =VLOOKUP(A10, Observed_Lookup!A:G, 6, FALSE) | I10: =IF(F10="","",D10-G10) | J10: =IF(F10="","",E10-H10) | K10: =GCD(A10,D10) | L10: =A10/K10 | M10: =D10/K10 | N10: ="("&L10&","&M10&")" | O10: =(D10-A10)/E10 | P10: =V10/W10 | Q10: =A10 | R10: =D10 | S10: =A10 | T10: =2*A10+D10 | U10: =A10+2*D10 | V10: =8*(A10*(7117/768)+(D10-A10)*(1/64)) | W10: =4*E10*(7117/768) | X10: =W10-V10 | Y10: =IF(P10<1,"substrate-light / mass-heavy",IF(P10>1,"substrate-heavy / mass-light","balanced")) | Z10: =IF(F10="","",H10-IFERROR(VLOOKUP(A10, Observed_Lookup!A:G, 7, FALSE),"")) | AA10: =IF(Z10="","",Z10*931.49410242) | AB10: =8*(A10+IF(F10="",D10,G10))-17*(A10+IF(F10="",D10,G10))^(2/3)-(3/4)*A10*(A10-1)/(A10+IF(F10="",D10,G10))^(1/3)-22*(IF(F10="",D10,G10)-A10)^2/(A10+IF(F10="",D10,G10))+7*IF(AND(MOD(A10,2)=0,MOD(IF(F10="",D10,G10),2)=0),1,IF(AND(MOD(A10,2)=1,MOD(IF(F10="",D10,G10),2)=1),-1,0))/SQRT((A10+IF(F10="",D10,G10)))-(25/4)*IF(AND((A10/GCD(A10,IF(F10="",D10,G10)))=1,(IF(F10="",D10,G10)/GCD(A10,IF(F10="",D10,G10)))=1),0,1) | AC10: =IF(AA10="","",AA10-AB10) | AD10: =IF(AND(A10<=83,A10<>43,A10<>61),"clock-stable","clock-boundary") | AE10: engine_diff_from_observed | AF10: engine anchor F-24 differs from observed most-abundant F-19
A11: 10 | B11: Ne | C11: Neon | D11: =A11 + INT(A11 * INT((A11-1)/12) / 12) | E11: =A11+D11 | F11: =VLOOKUP(A11, Observed_Lookup!A:G, 4, FALSE) | G11: =VLOOKUP(A11, Observed_Lookup!A:G, 5, FALSE) | H11: =VLOOKUP(A11, Observed_Lookup!A:G, 6, FALSE) | I11: =IF(F11="","",D11-G11) | J11: =IF(F11="","",E11-H11) | K11: =GCD(A11,D11) | L11: =A11/K11 | M11: =D11/K11 | N11: ="("&L11&","&M11&")" | O11: =(D11-A11)/E11 | P11: =V11/W11 | Q11: =A11 | R11: =D11 | S11: =A11 | T11: =2*A11+D11 | U11: =A11+2*D11 | V11: =8*(A11*(7117/768)+(D11-A11)*(1/64)) | W11: =4*E11*(7117/768) | X11: =W11-V11 | Y11: =IF(P11<1,"substrate-light / mass-heavy",IF(P11>1,"substrate-heavy / mass-light","balanced")) | Z11: =IF(F11="","",H11-IFERROR(VLOOKUP(A11, Observed_Lookup!A:G, 7, FALSE),"")) | AA11: =IF(Z11="","",Z11*931.49410242) | AB11: =8*(A11+IF(F11="",D11,G11))-17*(A11+IF(F11="",D11,G11))^(2/3)-(3/4)*A11*(A11-1)/(A11+IF(F11="",D11,G11))^(1/3)-22*(IF(F11="",D11,G11)-A11)^2/(A11+IF(F11="",D11,G11))+7*IF(AND(MOD(A11,2)=0,MOD(IF(F11="",D11,G11),2)=0),1,IF(AND(MOD(A11,2)=1,MOD(IF(F11="",D11,G11),2)=1),-1,0))/SQRT((A11+IF(F11="",D11,G11)))-(25/4)*IF(AND((A11/GCD(A11,IF(F11="",D11,G11)))=1,(IF(F11="",D11,G11)/GCD(A11,IF(F11="",D11,G11)))=1),0,1) | AC11: =IF(AA11="","",AA11-AB11) | AD11: =IF(AND(A11<=83,A11<>43,A11<>61),"clock-stable","clock-boundary") | AE11: engine_diff_from_observed | AF11: engine anchor Ne-27 differs from observed most-abundant Ne-20
A12: 11 | B12: Na | C12: Sodium | D12: =A12 + INT(A12 * INT((A12-1)/12) / 12) | E12: =A12+D12 | F12: =VLOOKUP(A12, Observed_Lookup!A:G, 4, FALSE) | G12: =VLOOKUP(A12, Observed_Lookup!A:G, 5, FALSE) | H12: =VLOOKUP(A12, Observed_Lookup!A:G, 6, FALSE) | I12: =IF(F12="","",D12-G12) | J12: =IF(F12="","",E12-H12) | K12: =GCD(A12,D12) | L12: =A12/K12 | M12: =D12/K12 | N12: ="("&L12&","&M12&")" | O12: =(D12-A12)/E12 | P12: =V12/W12 | Q12: =A12 | R12: =D12 | S12: =A12 | T12: =2*A12+D12 | U12: =A12+2*D12 | V12: =8*(A12*(7117/768)+(D12-A12)*(1/64)) | W12: =4*E12*(7117/768) | X12: =W12-V12 | Y12: =IF(P12<1,"substrate-light / mass-heavy",IF(P12>1,"substrate-heavy / mass-light","balanced")) | Z12: =IF(F12="","",H12-IFERROR(VLOOKUP(A12, Observed_Lookup!A:G, 7, FALSE),"")) | AA12: =IF(Z12="","",Z12*931.49410242) | AB12: =8*(A12+IF(F12="",D12,G12))-17*(A12+IF(F12="",D12,G12))^(2/3)-(3/4)*A12*(A12-1)/(A12+IF(F12="",D12,G12))^(1/3)-22*(IF(F12="",D12,G12)-A12)^2/(A12+IF(F12="",D12,G12))+7*IF(AND(MOD(A12,2)=0,MOD(IF(F12="",D12,G12),2)=0),1,IF(AND(MOD(A12,2)=1,MOD(IF(F12="",D12,G12),2)=1),-1,0))/SQRT((A12+IF(F12="",D12,G12)))-(25/4)*IF(AND((A12/GCD(A12,IF(F12="",D12,G12)))=1,(IF(F12="",D12,G12)/GCD(A12,IF(F12="",D12,G12)))=1),0,1) | AC12: =IF(AA12="","",AA12-AB12) | AD12: =IF(AND(A12<=83,A12<>43,A12<>61),"clock-stable","clock-boundary") | AE12: engine_diff_from_observed | AF12: engine anchor Na-31 differs from observed most-abundant Na-23
A13: 12 | B13: Mg | C13: Magnesium | D13: =A13 + INT(A13 * INT((A13-1)/12) / 12) | E13: =A13+D13 | F13: =VLOOKUP(A13, Observed_Lookup!A:G, 4, FALSE) | G13: =VLOOKUP(A13, Observed_Lookup!A:G, 5, FALSE) | H13: =VLOOKUP(A13, Observed_Lookup!A:G, 6, FALSE) | I13: =IF(F13="","",D13-G13) | J13: =IF(F13="","",E13-H13) | K13: =GCD(A13,D13) | L13: =A13/K13 | M13: =D13/K13 | N13: ="("&L13&","&M13&")" | O13: =(D13-A13)/E13 | P13: =V13/W13 | Q13: =A13 | R13: =D13 | S13: =A13 | T13: =2*A13+D13 | U13: =A13+2*D13 | V13: =8*(A13*(7117/768)+(D13-A13)*(1/64)) | W13: =4*E13*(7117/768) | X13: =W13-V13 | Y13: =IF(P13<1,"substrate-light / mass-heavy",IF(P13>1,"substrate-heavy / mass-light","balanced")) | Z13: =IF(F13="","",H13-IFERROR(VLOOKUP(A13, Observed_Lookup!A:G, 7, FALSE),"")) | AA13: =IF(Z13="","",Z13*931.49410242) | AB13: =8*(A13+IF(F13="",D13,G13))-17*(A13+IF(F13="",D13,G13))^(2/3)-(3/4)*A13*(A13-1)/(A13+IF(F13="",D13,G13))^(1/3)-22*(IF(F13="",D13,G13)-A13)^2/(A13+IF(F13="",D13,G13))+7*IF(AND(MOD(A13,2)=0,MOD(IF(F13="",D13,G13),2)=0),1,IF(AND(MOD(A13,2)=1,MOD(IF(F13="",D13,G13),2)=1),-1,0))/SQRT((A13+IF(F13="",D13,G13)))-(25/4)*IF(AND((A13/GCD(A13,IF(F13="",D13,G13)))=1,(IF(F13="",D13,G13)/GCD(A13,IF(F13="",D13,G13)))=1),0,1) | AC13: =IF(AA13="","",AA13-AB13) | AD13: =IF(AND(A13<=83,A13<>43,A13<>61),"clock-stable","clock-boundary") | AE13: engine_diff_from_observed | AF13: engine anchor Mg-35 differs from observed most-abundant Mg-24
A14: 13 | B14: Al | C14: Aluminum | D14: =A14 + INT(A14 * INT((A14-1)/12) / 12) | E14: =A14+D14 | F14: =VLOOKUP(A14, Observed_Lookup!A:G, 4, FALSE) | G14: =VLOOKUP(A14, Observed_Lookup!A:G, 5, FALSE) | H14: =VLOOKUP(A14, Observed_Lookup!A:G, 6, FALSE) | I14: =IF(F14="","",D14-G14) | J14: =IF(F14="","",E14-H14) | K14: =GCD(A14,D14) | L14: =A14/K14 | M14: =D14/K14 | N14: ="("&L14&","&M14&")" | O14: =(D14-A14)/E14 | P14: =V14/W14 | Q14: =A14 | R14: =D14 | S14: =A14 | T14: =2*A14+D14 | U14: =A14+2*D14 | V14: =8*(A14*(7117/768)+(D14-A14)*(1/64)) | W14: =4*E14*(7117/768) | X14: =W14-V14 | Y14: =IF(P14<1,"substrate-light / mass-heavy",IF(P14>1,"substrate-heavy / mass-light","balanced")) | Z14: =IF(F14="","",H14-IFERROR(VLOOKUP(A14, Observed_Lookup!A:G, 7, FALSE),"")) | AA14: =IF(Z14="","",Z14*931.49410242) | AB14: =8*(A14+IF(F14="",D14,G14))-17*(A14+IF(F14="",D14,G14))^(2/3)-(3/4)*A14*(A14-1)/(A14+IF(F14="",D14,G14))^(1/3)-22*(IF(F14="",D14,G14)-A14)^2/(A14+IF(F14="",D14,G14))+7*IF(AND(MOD(A14,2)=0,MOD(IF(F14="",D14,G14),2)=0),1,IF(AND(MOD(A14,2)=1,MOD(IF(F14="",D14,G14),2)=1),-1,0))/SQRT((A14+IF(F14="",D14,G14)))-(25/4)*IF(AND((A14/GCD(A14,IF(F14="",D14,G14)))=1,(IF(F14="",D14,G14)/GCD(A14,IF(F14="",D14,G14)))=1),0,1) | AC14: =IF(AA14="","",AA14-AB14) | AD14: =IF(AND(A14<=83,A14<>43,A14<>61),"clock-stable","clock-boundary") | AE14: engine_diff_from_observed | AF14: engine anchor Al-26 differs from observed most-abundant Al-27
A15: 14 | B15: Si | C15: Silicon | D15: =A15 + INT(A15 * INT((A15-1)/12) / 12) | E15: =A15+D15 | F15: =VLOOKUP(A15, Observed_Lookup!A:G, 4, FALSE) | G15: =VLOOKUP(A15, Observed_Lookup!A:G, 5, FALSE) | H15: =VLOOKUP(A15, Observed_Lookup!A:G, 6, FALSE) | I15: =IF(F15="","",D15-G15) | J15: =IF(F15="","",E15-H15) | K15: =GCD(A15,D15) | L15: =A15/K15 | M15: =D15/K15 | N15: ="("&L15&","&M15&")" | O15: =(D15-A15)/E15 | P15: =V15/W15 | Q15: =A15 | R15: =D15 | S15: =A15 | T15: =2*A15+D15 | U15: =A15+2*D15 | V15: =8*(A15*(7117/768)+(D15-A15)*(1/64)) | W15: =4*E15*(7117/768) | X15: =W15-V15 | Y15: =IF(P15<1,"substrate-light / mass-heavy",IF(P15>1,"substrate-heavy / mass-light","balanced")) | Z15: =IF(F15="","",H15-IFERROR(VLOOKUP(A15, Observed_Lookup!A:G, 7, FALSE),"")) | AA15: =IF(Z15="","",Z15*931.49410242) | AB15: =8*(A15+IF(F15="",D15,G15))-17*(A15+IF(F15="",D15,G15))^(2/3)-(3/4)*A15*(A15-1)/(A15+IF(F15="",D15,G15))^(1/3)-22*(IF(F15="",D15,G15)-A15)^2/(A15+IF(F15="",D15,G15))+7*IF(AND(MOD(A15,2)=0,MOD(IF(F15="",D15,G15),2)=0),1,IF(AND(MOD(A15,2)=1,MOD(IF(F15="",D15,G15),2)=1),-1,0))/SQRT((A15+IF(F15="",D15,G15)))-(25/4)*IF(AND((A15/GCD(A15,IF(F15="",D15,G15)))=1,(IF(F15="",D15,G15)/GCD(A15,IF(F15="",D15,G15)))=1),0,1) | AC15: =IF(AA15="","",AA15-AB15) | AD15: =IF(AND(A15<=83,A15<>43,A15<>61),"clock-stable","clock-boundary") | AE15: engine_diff_from_observed | AF15: engine anchor Si-29 differs from observed most-abundant Si-28
A16: 15 | B16: P | C16: Phosphorus | D16: =A16 + INT(A16 * INT((A16-1)/12) / 12) | E16: =A16+D16 | F16: =VLOOKUP(A16, Observed_Lookup!A:G, 4, FALSE) | G16: =VLOOKUP(A16, Observed_Lookup!A:G, 5, FALSE) | H16: =VLOOKUP(A16, Observed_Lookup!A:G, 6, FALSE) | I16: =IF(F16="","",D16-G16) | J16: =IF(F16="","",E16-H16) | K16: =GCD(A16,D16) | L16: =A16/K16 | M16: =D16/K16 | N16: ="("&L16&","&M16&")" | O16: =(D16-A16)/E16 | P16: =V16/W16 | Q16: =A16 | R16: =D16 | S16: =A16 | T16: =2*A16+D16 | U16: =A16+2*D16 | V16: =8*(A16*(7117/768)+(D16-A16)*(1/64)) | W16: =4*E16*(7117/768) | X16: =W16-V16 | Y16: =IF(P16<1,"substrate-light / mass-heavy",IF(P16>1,"substrate-heavy / mass-light","balanced")) | Z16: =IF(F16="","",H16-IFERROR(VLOOKUP(A16, Observed_Lookup!A:G, 7, FALSE),"")) | AA16: =IF(Z16="","",Z16*931.49410242) | AB16: =8*(A16+IF(F16="",D16,G16))-17*(A16+IF(F16="",D16,G16))^(2/3)-(3/4)*A16*(A16-1)/(A16+IF(F16="",D16,G16))^(1/3)-22*(IF(F16="",D16,G16)-A16)^2/(A16+IF(F16="",D16,G16))+7*IF(AND(MOD(A16,2)=0,MOD(IF(F16="",D16,G16),2)=0),1,IF(AND(MOD(A16,2)=1,MOD(IF(F16="",D16,G16),2)=1),-1,0))/SQRT((A16+IF(F16="",D16,G16)))-(25/4)*IF(AND((A16/GCD(A16,IF(F16="",D16,G16)))=1,(IF(F16="",D16,G16)/GCD(A16,IF(F16="",D16,G16)))=1),0,1) | AC16: =IF(AA16="","",AA16-AB16) | AD16: =IF(AND(A16<=83,A16<>43,A16<>61),"clock-stable","clock-boundary") | AE16: engine_diff_from_observed | AF16: engine anchor P-32 differs from observed most-abundant P-31
A17: 16 | B17: S | C17: Sulfur | D17: =A17 + INT(A17 * INT((A17-1)/12) / 12) | E17: =A17+D17 | F17: =VLOOKUP(A17, Observed_Lookup!A:G, 4, FALSE) | G17: =VLOOKUP(A17, Observed_Lookup!A:G, 5, FALSE) | H17: =VLOOKUP(A17, Observed_Lookup!A:G, 6, FALSE) | I17: =IF(F17="","",D17-G17) | J17: =IF(F17="","",E17-H17) | K17: =GCD(A17,D17) | L17: =A17/K17 | M17: =D17/K17 | N17: ="("&L17&","&M17&")" | O17: =(D17-A17)/E17 | P17: =V17/W17 | Q17: =A17 | R17: =D17 | S17: =A17 | T17: =2*A17+D17 | U17: =A17+2*D17 | V17: =8*(A17*(7117/768)+(D17-A17)*(1/64)) | W17: =4*E17*(7117/768) | X17: =W17-V17 | Y17: =IF(P17<1,"substrate-light / mass-heavy",IF(P17>1,"substrate-heavy / mass-light","balanced")) | Z17: =IF(F17="","",H17-IFERROR(VLOOKUP(A17, Observed_Lookup!A:G, 7, FALSE),"")) | AA17: =IF(Z17="","",Z17*931.49410242) | AB17: =8*(A17+IF(F17="",D17,G17))-17*(A17+IF(F17="",D17,G17))^(2/3)-(3/4)*A17*(A17-1)/(A17+IF(F17="",D17,G17))^(1/3)-22*(IF(F17="",D17,G17)-A17)^2/(A17+IF(F17="",D17,G17))+7*IF(AND(MOD(A17,2)=0,MOD(IF(F17="",D17,G17),2)=0),1,IF(AND(MOD(A17,2)=1,MOD(IF(F17="",D17,G17),2)=1),-1,0))/SQRT((A17+IF(F17="",D17,G17)))-(25/4)*IF(AND((A17/GCD(A17,IF(F17="",D17,G17)))=1,(IF(F17="",D17,G17)/GCD(A17,IF(F17="",D17,G17)))=1),0,1) | AC17: =IF(AA17="","",AA17-AB17) | AD17: =IF(AND(A17<=83,A17<>43,A17<>61),"clock-stable","clock-boundary") | AE17: engine_diff_from_observed | AF17: engine anchor S-36 differs from observed most-abundant S-32
A18: 17 | B18: Cl | C18: Chlorine | D18: =A18 + INT(A18 * INT((A18-1)/12) / 12) | E18: =A18+D18 | F18: =VLOOKUP(A18, Observed_Lookup!A:G, 4, FALSE) | G18: =VLOOKUP(A18, Observed_Lookup!A:G, 5, FALSE) | H18: =VLOOKUP(A18, Observed_Lookup!A:G, 6, FALSE) | I18: =IF(F18="","",D18-G18) | J18: =IF(F18="","",E18-H18) | K18: =GCD(A18,D18) | L18: =A18/K18 | M18: =D18/K18 | N18: ="("&L18&","&M18&")" | O18: =(D18-A18)/E18 | P18: =V18/W18 | Q18: =A18 | R18: =D18 | S18: =A18 | T18: =2*A18+D18 | U18: =A18+2*D18 | V18: =8*(A18*(7117/768)+(D18-A18)*(1/64)) | W18: =4*E18*(7117/768) | X18: =W18-V18 | Y18: =IF(P18<1,"substrate-light / mass-heavy",IF(P18>1,"substrate-heavy / mass-light","balanced")) | Z18: =IF(F18="","",H18-IFERROR(VLOOKUP(A18, Observed_Lookup!A:G, 7, FALSE),"")) | AA18: =IF(Z18="","",Z18*931.49410242) | AB18: =8*(A18+IF(F18="",D18,G18))-17*(A18+IF(F18="",D18,G18))^(2/3)-(3/4)*A18*(A18-1)/(A18+IF(F18="",D18,G18))^(1/3)-22*(IF(F18="",D18,G18)-A18)^2/(A18+IF(F18="",D18,G18))+7*IF(AND(MOD(A18,2)=0,MOD(IF(F18="",D18,G18),2)=0),1,IF(AND(MOD(A18,2)=1,MOD(IF(F18="",D18,G18),2)=1),-1,0))/SQRT((A18+IF(F18="",D18,G18)))-(25/4)*IF(AND((A18/GCD(A18,IF(F18="",D18,G18)))=1,(IF(F18="",D18,G18)/GCD(A18,IF(F18="",D18,G18)))=1),0,1) | AC18: =IF(AA18="","",AA18-AB18) | AD18: =IF(AND(A18<=83,A18<>43,A18<>61),"clock-stable","clock-boundary") | AE18: engine_diff_from_observed | AF18: engine anchor Cl-39 differs from observed most-abundant Cl-35
... A40: 39 | B40: Y | C40: Yttrium | D40: =A40 + INT(A40 * INT((A40-1)/12) / 12) | E40: =A40+D40 | F40: =VLOOKUP(A40, Observed_Lookup!A:G, 4, FALSE) | G40: =VLOOKUP(A40, Observed_Lookup!A:G, 5, FALSE) | H40: =VLOOKUP(A40, Observed_Lookup!A:G, 6, FALSE) | I40: =IF(F40="","",D40-G40) | J40: =IF(F40="","",E40-H40) | K40: =GCD(A40,D40) | L40: =A40/K40 | M40: =D40/K40 | N40: ="("&L40&","&M40&")" | O40: =(D40-A40)/E40 | P40: =V40/W40 | Q40: =A40 | R40: =D40 | S40: =A40 | T40: =2*A40+D40 | U40: =A40+2*D40 | V40: =8*(A40*(7117/768)+(D40-A40)*(1/64)) | W40: =4*E40*(7117/768) | X40: =W40-V40 | Y40: =IF(P40<1,"substrate-light / mass-heavy",IF(P40>1,"substrate-heavy / mass-light","balanced")) | Z40: =IF(F40="","",H40-IFERROR(VLOOKUP(A40, Observed_Lookup!A:G, 7, FALSE),"")) | AA40: =IF(Z40="","",Z40*931.49410242) | AB40: =8*(A40+IF(F40="",D40,G40))-17*(A40+IF(F40="",D40,G40))^(2/3)-(3/4)*A40*(A40-1)/(A40+IF(F40="",D40,G40))^(1/3)-22*(IF(F40="",D40,G40)-A40)^2/(A40+IF(F40="",D40,G40))+7*IF(AND(MOD(A40,2)=0,MOD(IF(F40="",D40,G40),2)=0),1,IF(AND(MOD(A40,2)=1,MOD(IF(F40="",D40,G40),2)=1),-1,0))/SQRT((A40+IF(F40="",D40,G40)))-(25/4)*IF(AND((A40/GCD(A40,IF(F40="",D40,G40)))=1,(IF(F40="",D40,G40)/GCD(A40,IF(F40="",D40,G40)))=1),0,1) | AC40: =IF(AA40="","",AA40-AB40) | AD40: =IF(AND(A40<=83,A40<>43,A40<>61),"clock-stable","clock-boundary") | AE40: engine_diff_from_observed | AF40: engine anchor Y-84 differs from observed most-abundant Y-89
A41: 40 | B41: Zr | C41: Zirconium | D41: =A41 + INT(A41 * INT((A41-1)/12) / 12) | E41: =A41+D41 | F41: =VLOOKUP(A41, Observed_Lookup!A:G, 4, FALSE) | G41: =VLOOKUP(A41, Observed_Lookup!A:G, 5, FALSE) | H41: =VLOOKUP(A41, Observed_Lookup!A:G, 6, FALSE) | I41: =IF(F41="","",D41-G41) | J41: =IF(F41="","",E41-H41) | K41: =GCD(A41,D41) | L41: =A41/K41 | M41: =D41/K41 | N41: ="("&L41&","&M41&")" | O41: =(D41-A41)/E41 | P41: =V41/W41 | Q41: =A41 | R41: =D41 | S41: =A41 | T41: =2*A41+D41 | U41: =A41+2*D41 | V41: =8*(A41*(7117/768)+(D41-A41)*(1/64)) | W41: =4*E41*(7117/768) | X41: =W41-V41 | Y41: =IF(P41<1,"substrate-light / mass-heavy",IF(P41>1,"substrate-heavy / mass-light","balanced")) | Z41: =IF(F41="","",H41-IFERROR(VLOOKUP(A41, Observed_Lookup!A:G, 7, FALSE),"")) | AA41: =IF(Z41="","",Z41*931.49410242) | AB41: =8*(A41+IF(F41="",D41,G41))-17*(A41+IF(F41="",D41,G41))^(2/3)-(3/4)*A41*(A41-1)/(A41+IF(F41="",D41,G41))^(1/3)-22*(IF(F41="",D41,G41)-A41)^2/(A41+IF(F41="",D41,G41))+7*IF(AND(MOD(A41,2)=0,MOD(IF(F41="",D41,G41),2)=0),1,IF(AND(MOD(A41,2)=1,MOD(IF(F41="",D41,G41),2)=1),-1,0))/SQRT((A41+IF(F41="",D41,G41)))-(25/4)*IF(AND((A41/GCD(A41,IF(F41="",D41,G41)))=1,(IF(F41="",D41,G41)/GCD(A41,IF(F41="",D41,G41)))=1),0,1) | AC41: =IF(AA41="","",AA41-AB41) | AD41: =IF(AND(A41<=83,A41<>43,A41<>61),"clock-stable","clock-boundary") | AE41: engine_matches_observed
A42: 41 | B42: Nb | C42: Niobium | D42: =A42 + INT(A42 * INT((A42-1)/12) / 12) | E42: =A42+D42 | F42: =VLOOKUP(A42, Observed_Lookup!A:G, 4, FALSE) | G42: =VLOOKUP(A42, Observed_Lookup!A:G, 5, FALSE) | H42: =VLOOKUP(A42, Observed_Lookup!A:G, 6, FALSE) | I42: =IF(F42="","",D42-G42) | J42: =IF(F42="","",E42-H42) | K42: =GCD(A42,D42) | L42: =A42/K42 | M42: =D42/K42 | N42: ="("&L42&","&M42&")" | O42: =(D42-A42)/E42 | P42: =V42/W42 | Q42: =A42 | R42: =D42 | S42: =A42 | T42: =2*A42+D42 | U42: =A42+2*D42 | V42: =8*(A42*(7117/768)+(D42-A42)*(1/64)) | W42: =4*E42*(7117/768) | X42: =W42-V42 | Y42: =IF(P42<1,"substrate-light / mass-heavy",IF(P42>1,"substrate-heavy / mass-light","balanced")) | Z42: =IF(F42="","",H42-IFERROR(VLOOKUP(A42, Observed_Lookup!A:G, 7, FALSE),"")) | AA42: =IF(Z42="","",Z42*931.49410242) | AB42: =8*(A42+IF(F42="",D42,G42))-17*(A42+IF(F42="",D42,G42))^(2/3)-(3/4)*A42*(A42-1)/(A42+IF(F42="",D42,G42))^(1/3)-22*(IF(F42="",D42,G42)-A42)^2/(A42+IF(F42="",D42,G42))+7*IF(AND(MOD(A42,2)=0,MOD(IF(F42="",D42,G42),2)=0),1,IF(AND(MOD(A42,2)=1,MOD(IF(F42="",D42,G42),2)=1),-1,0))/SQRT((A42+IF(F42="",D42,G42)))-(25/4)*IF(AND((A42/GCD(A42,IF(F42="",D42,G42)))=1,(IF(F42="",D42,G42)/GCD(A42,IF(F42="",D42,G42)))=1),0,1) | AC42: =IF(AA42="","",AA42-AB42) | AD42: =IF(AND(A42<=83,A42<>43,A42<>61),"clock-stable","clock-boundary") | AE42: engine_diff_from_observed | AF42: engine anchor Nb-95 differs from observed most-abundant Nb-93
A43: 42 | B43: Mo | C43: Molybdenum | D43: =A43 + INT(A43 * INT((A43-1)/12) / 12) | E43: =A43+D43 | F43: =VLOOKUP(A43, Observed_Lookup!A:G, 4, FALSE) | G43: =VLOOKUP(A43, Observed_Lookup!A:G, 5, FALSE) | H43: =VLOOKUP(A43, Observed_Lookup!A:G, 6, FALSE) | I43: =IF(F43="","",D43-G43) | J43: =IF(F43="","",E43-H43) | K43: =GCD(A43,D43) | L43: =A43/K43 | M43: =D43/K43 | N43: ="("&L43&","&M43&")" | O43: =(D43-A43)/E43 | P43: =V43/W43 | Q43: =A43 | R43: =D43 | S43: =A43 | T43: =2*A43+D43 | U43: =A43+2*D43 | V43: =8*(A43*(7117/768)+(D43-A43)*(1/64)) | W43: =4*E43*(7117/768) | X43: =W43-V43 | Y43: =IF(P43<1,"substrate-light / mass-heavy",IF(P43>1,"substrate-heavy / mass-light","balanced")) | Z43: =IF(F43="","",H43-IFERROR(VLOOKUP(A43, Observed_Lookup!A:G, 7, FALSE),"")) | AA43: =IF(Z43="","",Z43*931.49410242) | AB43: =8*(A43+IF(F43="",D43,G43))-17*(A43+IF(F43="",D43,G43))^(2/3)-(3/4)*A43*(A43-1)/(A43+IF(F43="",D43,G43))^(1/3)-22*(IF(F43="",D43,G43)-A43)^2/(A43+IF(F43="",D43,G43))+7*IF(AND(MOD(A43,2)=0,MOD(IF(F43="",D43,G43),2)=0),1,IF(AND(MOD(A43,2)=1,MOD(IF(F43="",D43,G43),2)=1),-1,0))/SQRT((A43+IF(F43="",D43,G43)))-(25/4)*IF(AND((A43/GCD(A43,IF(F43="",D43,G43)))=1,(IF(F43="",D43,G43)/GCD(A43,IF(F43="",D43,G43)))=1),0,1) | AC43: =IF(AA43="","",AA43-AB43) | AD43: =IF(AND(A43<=83,A43<>43,A43<>61),"clock-stable","clock-boundary") | AE43: engine_diff_from_observed | AF43: engine anchor Mo-101 differs from observed most-abundant Mo-98
A44: 43 | B44: Tc | C44: Technetium | D44: =A44 + INT(A44 * INT((A44-1)/12) / 12) | E44: =A44+D44 | F44: =VLOOKUP(A44, Observed_Lookup!A:G, 4, FALSE) | G44: =VLOOKUP(A44, Observed_Lookup!A:G, 5, FALSE) | H44: =VLOOKUP(A44, Observed_Lookup!A:G, 6, FALSE) | I44: =IF(F44="","",D44-G44) | J44: =IF(F44="","",E44-H44) | K44: =GCD(A44,D44) | L44: =A44/K44 | M44: =D44/K44 | N44: ="("&L44&","&M44&")" | O44: =(D44-A44)/E44 | P44: =V44/W44 | Q44: =A44 | R44: =D44 | S44: =A44 | T44: =2*A44+D44 | U44: =A44+2*D44 | V44: =8*(A44*(7117/768)+(D44-A44)*(1/64)) | W44: =4*E44*(7117/768) | X44: =W44-V44 | Y44: =IF(P44<1,"substrate-light / mass-heavy",IF(P44>1,"substrate-heavy / mass-light","balanced")) | Z44: =IF(F44="","",H44-IFERROR(VLOOKUP(A44, Observed_Lookup!A:G, 7, FALSE),"")) | AA44: =IF(Z44="","",Z44*931.49410242) | AB44: =8*(A44+IF(F44="",D44,G44))-17*(A44+IF(F44="",D44,G44))^(2/3)-(3/4)*A44*(A44-1)/(A44+IF(F44="",D44,G44))^(1/3)-22*(IF(F44="",D44,G44)-A44)^2/(A44+IF(F44="",D44,G44))+7*IF(AND(MOD(A44,2)=0,MOD(IF(F44="",D44,G44),2)=0),1,IF(AND(MOD(A44,2)=1,MOD(IF(F44="",D44,G44),2)=1),-1,0))/SQRT((A44+IF(F44="",D44,G44)))-(25/4)*IF(AND((A44/GCD(A44,IF(F44="",D44,G44)))=1,(IF(F44="",D44,G44)/GCD(A44,IF(F44="",D44,G44)))=1),0,1) | AC44: =IF(AA44="","",AA44-AB44) | AD44: =IF(AND(A44<=83,A44<>43,A44<>61),"clock-stable","clock-boundary") | AE44: engine_diff_from_observed | AF44: engine anchor Tc-107 differs from observed most-abundant Tc-98
A45: 44 | B45: Ru | C45: Ruthenium | D45: =A45 + INT(A45 * INT((A45-1)/12) / 12) | E45: =A45+D45 | F45: =VLOOKUP(A45, Observed_Lookup!A:G, 4, FALSE) | G45: =VLOOKUP(A45, Observed_Lookup!A:G, 5, FALSE) | H45: =VLOOKUP(A45, Observed_Lookup!A:G, 6, FALSE) | I45: =IF(F45="","",D45-G45) | J45: =IF(F45="","",E45-H45) | K45: =GCD(A45,D45) | L45: =A45/K45 | M45: =D45/K45 | N45: ="("&L45&","&M45&")" | O45: =(D45-A45)/E45 | P45: =V45/W45 | Q45: =A45 | R45: =D45 | S45: =A45 | T45: =2*A45+D45 | U45: =A45+2*D45 | V45: =8*(A45*(7117/768)+(D45-A45)*(1/64)) | W45: =4*E45*(7117/768) | X45: =W45-V45 | Y45: =IF(P45<1,"substrate-light / mass-heavy",IF(P45>1,"substrate-heavy / mass-light","balanced")) | Z45: =IF(F45="","",H45-IFERROR(VLOOKUP(A45, Observed_Lookup!A:G, 7, FALSE),"")) | AA45: =IF(Z45="","",Z45*931.49410242) | AB45: =8*(A45+IF(F45="",D45,G45))-17*(A45+IF(F45="",D45,G45))^(2/3)-(3/4)*A45*(A45-1)/(A45+IF(F45="",D45,G45))^(1/3)-22*(IF(F45="",D45,G45)-A45)^2/(A45+IF(F45="",D45,G45))+7*IF(AND(MOD(A45,2)=0,MOD(IF(F45="",D45,G45),2)=0),1,IF(AND(MOD(A45,2)=1,MOD(IF(F45="",D45,G45),2)=1),-1,0))/SQRT((A45+IF(F45="",D45,G45)))-(25/4)*IF(AND((A45/GCD(A45,IF(F45="",D45,G45)))=1,(IF(F45="",D45,G45)/GCD(A45,IF(F45="",D45,G45)))=1),0,1) | AC45: =IF(AA45="","",AA45-AB45) | AD45: =IF(AND(A45<=83,A45<>43,A45<>61),"clock-stable","clock-boundary") | AE45: engine_diff_from_observed | AF45: engine anchor Ru-113 differs from observed most-abundant Ru-102
A46: 45 | B46: Rh | C46: Rhodium | D46: =A46 + INT(A46 * INT((A46-1)/12) / 12) | E46: =A46+D46 | F46: =VLOOKUP(A46, Observed_Lookup!A:G, 4, FALSE) | G46: =VLOOKUP(A46, Observed_Lookup!A:G, 5, FALSE) | H46: =VLOOKUP(A46, Observed_Lookup!A:G, 6, FALSE) | I46: =IF(F46="","",D46-G46) | J46: =IF(F46="","",E46-H46) | K46: =GCD(A46,D46) | L46: =A46/K46 | M46: =D46/K46 | N46: ="("&L46&","&M46&")" | O46: =(D46-A46)/E46 | P46: =V46/W46 | Q46: =A46 | R46: =D46 | S46: =A46 | T46: =2*A46+D46 | U46: =A46+2*D46 | V46: =8*(A46*(7117/768)+(D46-A46)*(1/64)) | W46: =4*E46*(7117/768) | X46: =W46-V46 | Y46: =IF(P46<1,"substrate-light / mass-heavy",IF(P46>1,"substrate-heavy / mass-light","balanced")) | Z46: =IF(F46="","",H46-IFERROR(VLOOKUP(A46, Observed_Lookup!A:G, 7, FALSE),"")) | AA46: =IF(Z46="","",Z46*931.49410242) | AB46: =8*(A46+IF(F46="",D46,G46))-17*(A46+IF(F46="",D46,G46))^(2/3)-(3/4)*A46*(A46-1)/(A46+IF(F46="",D46,G46))^(1/3)-22*(IF(F46="",D46,G46)-A46)^2/(A46+IF(F46="",D46,G46))+7*IF(AND(MOD(A46,2)=0,MOD(IF(F46="",D46,G46),2)=0),1,IF(AND(MOD(A46,2)=1,MOD(IF(F46="",D46,G46),2)=1),-1,0))/SQRT((A46+IF(F46="",D46,G46)))-(25/4)*IF(AND((A46/GCD(A46,IF(F46="",D46,G46)))=1,(IF(F46="",D46,G46)/GCD(A46,IF(F46="",D46,G46)))=1),0,1) | AC46: =IF(AA46="","",AA46-AB46) | AD46: =IF(AND(A46<=83,A46<>43,A46<>61),"clock-stable","clock-boundary") | AE46: engine_diff_from_observed | AF46: engine anchor Rh-120 differs from observed most-abundant Rh-103
A47: 46 | B47: Pd | C47: Palladium | D47: =A47 + INT(A47 * INT((A47-1)/12) / 12) | E47: =A47+D47 | F47: =VLOOKUP(A47, Observed_Lookup!A:G, 4, FALSE) | G47: =VLOOKUP(A47, Observed_Lookup!A:G, 5, FALSE) | H47: =VLOOKUP(A47, Observed_Lookup!A:G, 6, FALSE) | I47: =IF(F47="","",D47-G47) | J47: =IF(F47="","",E47-H47) | K47: =GCD(A47,D47) | L47: =A47/K47 | M47: =D47/K47 | N47: ="("&L47&","&M47&")" | O47: =(D47-A47)/E47 | P47: =V47/W47 | Q47: =A47 | R47: =D47 | S47: =A47 | T47: =2*A47+D47 | U47: =A47+2*D47 | V47: =8*(A47*(7117/768)+(D47-A47)*(1/64)) | W47: =4*E47*(7117/768) | X47: =W47-V47 | Y47: =IF(P47<1,"substrate-light / mass-heavy",IF(P47>1,"substrate-heavy / mass-light","balanced")) | Z47: =IF(F47="","",H47-IFERROR(VLOOKUP(A47, Observed_Lookup!A:G, 7, FALSE),"")) | AA47: =IF(Z47="","",Z47*931.49410242) | AB47: =8*(A47+IF(F47="",D47,G47))-17*(A47+IF(F47="",D47,G47))^(2/3)-(3/4)*A47*(A47-1)/(A47+IF(F47="",D47,G47))^(1/3)-22*(IF(F47="",D47,G47)-A47)^2/(A47+IF(F47="",D47,G47))+7*IF(AND(MOD(A47,2)=0,MOD(IF(F47="",D47,G47),2)=0),1,IF(AND(MOD(A47,2)=1,MOD(IF(F47="",D47,G47),2)=1),-1,0))/SQRT((A47+IF(F47="",D47,G47)))-(25/4)*IF(AND((A47/GCD(A47,IF(F47="",D47,G47)))=1,(IF(F47="",D47,G47)/GCD(A47,IF(F47="",D47,G47)))=1),0,1) | AC47: =IF(AA47="","",AA47-AB47) | AD47: =IF(AND(A47<=83,A47<>43,A47<>61),"clock-stable","clock-boundary") | AE47: engine_diff_from_observed | AF47: engine anchor Pd-126 differs from observed most-abundant Pd-106
A48: 47 | B48: Ag | C48: Silver | D48: =A48 + INT(A48 * INT((A48-1)/12) / 12) | E48: =A48+D48 | F48: =VLOOKUP(A48, Observed_Lookup!A:G, 4, FALSE) | G48: =VLOOKUP(A48, Observed_Lookup!A:G, 5, FALSE) | H48: =VLOOKUP(A48, Observed_Lookup!A:G, 6, FALSE) | I48: =IF(F48="","",D48-G48) | J48: =IF(F48="","",E48-H48) | K48: =GCD(A48,D48) | L48: =A48/K48 | M48: =D48/K48 | N48: ="("&L48&","&M48&")" | O48: =(D48-A48)/E48 | P48: =V48/W48 | Q48: =A48 | R48: =D48 | S48: =A48 | T48: =2*A48+D48 | U48: =A48+2*D48 | V48: =8*(A48*(7117/768)+(D48-A48)*(1/64)) | W48: =4*E48*(7117/768) | X48: =W48-V48 | Y48: =IF(P48<1,"substrate-light / mass-heavy",IF(P48>1,"substrate-heavy / mass-light","balanced")) | Z48: =IF(F48="","",H48-IFERROR(VLOOKUP(A48, Observed_Lookup!A:G, 7, FALSE),"")) | AA48: =IF(Z48="","",Z48*931.49410242) | AB48: =8*(A48+IF(F48="",D48,G48))-17*(A48+IF(F48="",D48,G48))^(2/3)-(3/4)*A48*(A48-1)/(A48+IF(F48="",D48,G48))^(1/3)-22*(IF(F48="",D48,G48)-A48)^2/(A48+IF(F48="",D48,G48))+7*IF(AND(MOD(A48,2)=0,MOD(IF(F48="",D48,G48),2)=0),1,IF(AND(MOD(A48,2)=1,MOD(IF(F48="",D48,G48),2)=1),-1,0))/SQRT((A48+IF(F48="",D48,G48)))-(25/4)*IF(AND((A48/GCD(A48,IF(F48="",D48,G48)))=1,(IF(F48="",D48,G48)/GCD(A48,IF(F48="",D48,G48)))=1),0,1) | AC48: =IF(AA48="","",AA48-AB48) | AD48: =IF(AND(A48<=83,A48<>43,A48<>61),"clock-stable","clock-boundary") | AE48: engine_diff_from_observed | AF48: engine anchor Ag-133 differs from observed most-abundant Ag-107
A49: 48 | B49: Cd | C49: Cadmium | D49: =A49 + INT(A49 * INT((A49-1)/12) / 12) | E49: =A49+D49 | F49: =VLOOKUP(A49, Observed_Lookup!A:G, 4, FALSE) | G49: =VLOOKUP(A49, Observed_Lookup!A:G, 5, FALSE) | H49: =VLOOKUP(A49, Observed_Lookup!A:G, 6, FALSE) | I49: =IF(F49="","",D49-G49) | J49: =IF(F49="","",E49-H49) | K49: =GCD(A49,D49) | L49: =A49/K49 | M49: =D49/K49 | N49: ="("&L49&","&M49&")" | O49: =(D49-A49)/E49 | P49: =V49/W49 | Q49: =A49 | R49: =D49 | S49: =A49 | T49: =2*A49+D49 | U49: =A49+2*D49 | V49: =8*(A49*(7117/768)+(D49-A49)*(1/64)) | W49: =4*E49*(7117/768) | X49: =W49-V49 | Y49: =IF(P49<1,"substrate-light / mass-heavy",IF(P49>1,"substrate-heavy / mass-light","balanced")) | Z49: =IF(F49="","",H49-IFERROR(VLOOKUP(A49, Observed_Lookup!A:G, 7, FALSE),"")) | AA49: =IF(Z49="","",Z49*931.49410242) | AB49: =8*(A49+IF(F49="",D49,G49))-17*(A49+IF(F49="",D49,G49))^(2/3)-(3/4)*A49*(A49-1)/(A49+IF(F49="",D49,G49))^(1/3)-22*(IF(F49="",D49,G49)-A49)^2/(A49+IF(F49="",D49,G49))+7*IF(AND(MOD(A49,2)=0,MOD(IF(F49="",D49,G49),2)=0),1,IF(AND(MOD(A49,2)=1,MOD(IF(F49="",D49,G49),2)=1),-1,0))/SQRT((A49+IF(F49="",D49,G49)))-(25/4)*IF(AND((A49/GCD(A49,IF(F49="",D49,G49)))=1,(IF(F49="",D49,G49)/GCD(A49,IF(F49="",D49,G49)))=1),0,1) | AC49: =IF(AA49="","",AA49-AB49) | AD49: =IF(AND(A49<=83,A49<>43,A49<>61),"clock-stable","clock-boundary") | AE49: engine_diff_from_observed | AF49: engine anchor Cd-140 differs from observed most-abundant Cd-114
A50: 49 | B50: In | C50: Indium | D50: =A50 + INT(A50 * INT((A50-1)/12) / 12) | E50: =A50+D50 | F50: =VLOOKUP(A50, Observed_Lookup!A:G, 4, FALSE) | G50: =VLOOKUP(A50, Observed_Lookup!A:G, 5, FALSE) | H50: =VLOOKUP(A50, Observed_Lookup!A:G, 6, FALSE) | I50: =IF(F50="","",D50-G50) | J50: =IF(F50="","",E50-H50) | K50: =GCD(A50,D50) | L50: =A50/K50 | M50: =D50/K50 | N50: ="("&L50&","&M50&")" | O50: =(D50-A50)/E50 | P50: =V50/W50 | Q50: =A50 | R50: =D50 | S50: =A50 | T50: =2*A50+D50 | U50: =A50+2*D50 | V50: =8*(A50*(7117/768)+(D50-A50)*(1/64)) | W50: =4*E50*(7117/768) | X50: =W50-V50 | Y50: =IF(P50<1,"substrate-light / mass-heavy",IF(P50>1,"substrate-heavy / mass-light","balanced")) | Z50: =IF(F50="","",H50-IFERROR(VLOOKUP(A50, Observed_Lookup!A:G, 7, FALSE),"")) | AA50: =IF(Z50="","",Z50*931.49410242) | AB50: =8*(A50+IF(F50="",D50,G50))-17*(A50+IF(F50="",D50,G50))^(2/3)-(3/4)*A50*(A50-1)/(A50+IF(F50="",D50,G50))^(1/3)-22*(IF(F50="",D50,G50)-A50)^2/(A50+IF(F50="",D50,G50))+7*IF(AND(MOD(A50,2)=0,MOD(IF(F50="",D50,G50),2)=0),1,IF(AND(MOD(A50,2)=1,MOD(IF(F50="",D50,G50),2)=1),-1,0))/SQRT((A50+IF(F50="",D50,G50)))-(25/4)*IF(AND((A50/GCD(A50,IF(F50="",D50,G50)))=1,(IF(F50="",D50,G50)/GCD(A50,IF(F50="",D50,G50)))=1),0,1) | AC50: =IF(AA50="","",AA50-AB50) | AD50: =IF(AND(A50<=83,A50<>43,A50<>61),"clock-stable","clock-boundary") | AE50: engine_diff_from_observed | AF50: engine anchor In-98 differs from observed most-abundant In-115
A51: 50 | B51: Sn | C51: Tin | D51: =A51 + INT(A51 * INT((A51-1)/12) / 12) | E51: =A51+D51 | F51: =VLOOKUP(A51, Observed_Lookup!A:G, 4, FALSE) | G51: =VLOOKUP(A51, Observed_Lookup!A:G, 5, FALSE) | H51: =VLOOKUP(A51, Observed_Lookup!A:G, 6, FALSE) | I51: =IF(F51="","",D51-G51) | J51: =IF(F51="","",E51-H51) | K51: =GCD(A51,D51) | L51: =A51/K51 | M51: =D51/K51 | N51: ="("&L51&","&M51&")" | O51: =(D51-A51)/E51 | P51: =V51/W51 | Q51: =A51 | R51: =D51 | S51: =A51 | T51: =2*A51+D51 | U51: =A51+2*D51 | V51: =8*(A51*(7117/768)+(D51-A51)*(1/64)) | W51: =4*E51*(7117/768) | X51: =W51-V51 | Y51: =IF(P51<1,"substrate-light / mass-heavy",IF(P51>1,"substrate-heavy / mass-light","balanced")) | Z51: =IF(F51="","",H51-IFERROR(VLOOKUP(A51, Observed_Lookup!A:G, 7, FALSE),"")) | AA51: =IF(Z51="","",Z51*931.49410242) | AB51: =8*(A51+IF(F51="",D51,G51))-17*(A51+IF(F51="",D51,G51))^(2/3)-(3/4)*A51*(A51-1)/(A51+IF(F51="",D51,G51))^(1/3)-22*(IF(F51="",D51,G51)-A51)^2/(A51+IF(F51="",D51,G51))+7*IF(AND(MOD(A51,2)=0,MOD(IF(F51="",D51,G51),2)=0),1,IF(AND(MOD(A51,2)=1,MOD(IF(F51="",D51,G51),2)=1),-1,0))/SQRT((A51+IF(F51="",D51,G51)))-(25/4)*IF(AND((A51/GCD(A51,IF(F51="",D51,G51)))=1,(IF(F51="",D51,G51)/GCD(A51,IF(F51="",D51,G51)))=1),0,1) | AC51: =IF(AA51="","",AA51-AB51) | AD51: =IF(AND(A51<=83,A51<>43,A51<>61),"clock-stable","clock-boundary") | AE51: engine_diff_from_observed | AF51: engine anchor Sn-104 differs from observed most-abundant Sn-120
A52: 51 | B52: Sb | C52: Antimony | D52: =A52 + INT(A52 * INT((A52-1)/12) / 12) | E52: =A52+D52 | F52: =VLOOKUP(A52, Observed_Lookup!A:G, 4, FALSE) | G52: =VLOOKUP(A52, Observed_Lookup!A:G, 5, FALSE) | H52: =VLOOKUP(A52, Observed_Lookup!A:G, 6, FALSE) | I52: =IF(F52="","",D52-G52) | J52: =IF(F52="","",E52-H52) | K52: =GCD(A52,D52) | L52: =A52/K52 | M52: =D52/K52 | N52: ="("&L52&","&M52&")" | O52: =(D52-A52)/E52 | P52: =V52/W52 | Q52: =A52 | R52: =D52 | S52: =A52 | T52: =2*A52+D52 | U52: =A52+2*D52 | V52: =8*(A52*(7117/768)+(D52-A52)*(1/64)) | W52: =4*E52*(7117/768) | X52: =W52-V52 | Y52: =IF(P52<1,"substrate-light / mass-heavy",IF(P52>1,"substrate-heavy / mass-light","balanced")) | Z52: =IF(F52="","",H52-IFERROR(VLOOKUP(A52, Observed_Lookup!A:G, 7, FALSE),"")) | AA52: =IF(Z52="","",Z52*931.49410242) | AB52: =8*(A52+IF(F52="",D52,G52))-17*(A52+IF(F52="",D52,G52))^(2/3)-(3/4)*A52*(A52-1)/(A52+IF(F52="",D52,G52))^(1/3)-22*(IF(F52="",D52,G52)-A52)^2/(A52+IF(F52="",D52,G52))+7*IF(AND(MOD(A52,2)=0,MOD(IF(F52="",D52,G52),2)=0),1,IF(AND(MOD(A52,2)=1,MOD(IF(F52="",D52,G52),2)=1),-1,0))/SQRT((A52+IF(F52="",D52,G52)))-(25/4)*IF(AND((A52/GCD(A52,IF(F52="",D52,G52)))=1,(IF(F52="",D52,G52)/GCD(A52,IF(F52="",D52,G52)))=1),0,1) | AC52: =IF(AA52="","",AA52-AB52) | AD52: =IF(AND(A52<=83,A52<>43,A52<>61),"clock-stable","clock-boundary") | AE52: engine_diff_from_observed | AF52: engine anchor Sb-110 differs from observed most-abundant Sb-121
A53: 52 | B53: Te | C53: Tellurium | D53: =A53 + INT(A53 * INT((A53-1)/12) / 12) | E53: =A53+D53 | F53: =VLOOKUP(A53, Observed_Lookup!A:G, 4, FALSE) | G53: =VLOOKUP(A53, Observed_Lookup!A:G, 5, FALSE) | H53: =VLOOKUP(A53, Observed_Lookup!A:G, 6, FALSE) | I53: =IF(F53="","",D53-G53) | J53: =IF(F53="","",E53-H53) | K53: =GCD(A53,D53) | L53: =A53/K53 | M53: =D53/K53 | N53: ="("&L53&","&M53&")" | O53: =(D53-A53)/E53 | P53: =V53/W53 | Q53: =A53 | R53: =D53 | S53: =A53 | T53: =2*A53+D53 | U53: =A53+2*D53 | V53: =8*(A53*(7117/768)+(D53-A53)*(1/64)) | W53: =4*E53*(7117/768) | X53: =W53-V53 | Y53: =IF(P53<1,"substrate-light / mass-heavy",IF(P53>1,"substrate-heavy / mass-light","balanced")) | Z53: =IF(F53="","",H53-IFERROR(VLOOKUP(A53, Observed_Lookup!A:G, 7, FALSE),"")) | AA53: =IF(Z53="","",Z53*931.49410242) | AB53: =8*(A53+IF(F53="",D53,G53))-17*(A53+IF(F53="",D53,G53))^(2/3)-(3/4)*A53*(A53-1)/(A53+IF(F53="",D53,G53))^(1/3)-22*(IF(F53="",D53,G53)-A53)^2/(A53+IF(F53="",D53,G53))+7*IF(AND(MOD(A53,2)=0,MOD(IF(F53="",D53,G53),2)=0),1,IF(AND(MOD(A53,2)=1,MOD(IF(F53="",D53,G53),2)=1),-1,0))/SQRT((A53+IF(F53="",D53,G53)))-(25/4)*IF(AND((A53/GCD(A53,IF(F53="",D53,G53)))=1,(IF(F53="",D53,G53)/GCD(A53,IF(F53="",D53,G53)))=1),0,1) | AC53: =IF(AA53="","",AA53-AB53) | AD53: =IF(AND(A53<=83,A53<>43,A53<>61),"clock-stable","clock-boundary") | AE53: engine_diff_from_observed | AF53: engine anchor Te-117 differs from observed most-abundant Te-130
... A79: 78 | B79: Pt | C79: Platinum | D79: =A79 + INT(A79 * INT((A79-1)/12) / 12) | E79: =A79+D79 | F79: =VLOOKUP(A79, Observed_Lookup!A:G, 4, FALSE) | G79: =VLOOKUP(A79, Observed_Lookup!A:G, 5, FALSE) | H79: =VLOOKUP(A79, Observed_Lookup!A:G, 6, FALSE) | I79: =IF(F79="","",D79-G79) | J79: =IF(F79="","",E79-H79) | K79: =GCD(A79,D79) | L79: =A79/K79 | M79: =D79/K79 | N79: ="("&L79&","&M79&")" | O79: =(D79-A79)/E79 | P79: =V79/W79 | Q79: =A79 | R79: =D79 | S79: =A79 | T79: =2*A79+D79 | U79: =A79+2*D79 | V79: =8*(A79*(7117/768)+(D79-A79)*(1/64)) | W79: =4*E79*(7117/768) | X79: =W79-V79 | Y79: =IF(P79<1,"substrate-light / mass-heavy",IF(P79>1,"substrate-heavy / mass-light","balanced")) | Z79: =IF(F79="","",H79-IFERROR(VLOOKUP(A79, Observed_Lookup!A:G, 7, FALSE),"")) | AA79: =IF(Z79="","",Z79*931.49410242) | AB79: =8*(A79+IF(F79="",D79,G79))-17*(A79+IF(F79="",D79,G79))^(2/3)-(3/4)*A79*(A79-1)/(A79+IF(F79="",D79,G79))^(1/3)-22*(IF(F79="",D79,G79)-A79)^2/(A79+IF(F79="",D79,G79))+7*IF(AND(MOD(A79,2)=0,MOD(IF(F79="",D79,G79),2)=0),1,IF(AND(MOD(A79,2)=1,MOD(IF(F79="",D79,G79),2)=1),-1,0))/SQRT((A79+IF(F79="",D79,G79)))-(25/4)*IF(AND((A79/GCD(A79,IF(F79="",D79,G79)))=1,(IF(F79="",D79,G79)/GCD(A79,IF(F79="",D79,G79)))=1),0,1) | AC79: =IF(AA79="","",AA79-AB79) | AD79: =IF(AND(A79<=83,A79<>43,A79<>61),"clock-stable","clock-boundary") | AE79: engine_diff_from_observed | AF79: engine anchor Pt-188 differs from observed most-abundant Pt-195
A80: 79 | B80: Au | C80: Gold | D80: =A80 + INT(A80 * INT((A80-1)/12) / 12) | E80: =A80+D80 | F80: =VLOOKUP(A80, Observed_Lookup!A:G, 4, FALSE) | G80: =VLOOKUP(A80, Observed_Lookup!A:G, 5, FALSE) | H80: =VLOOKUP(A80, Observed_Lookup!A:G, 6, FALSE) | I80: =IF(F80="","",D80-G80) | J80: =IF(F80="","",E80-H80) | K80: =GCD(A80,D80) | L80: =A80/K80 | M80: =D80/K80 | N80: ="("&L80&","&M80&")" | O80: =(D80-A80)/E80 | P80: =V80/W80 | Q80: =A80 | R80: =D80 | S80: =A80 | T80: =2*A80+D80 | U80: =A80+2*D80 | V80: =8*(A80*(7117/768)+(D80-A80)*(1/64)) | W80: =4*E80*(7117/768) | X80: =W80-V80 | Y80: =IF(P80<1,"substrate-light / mass-heavy",IF(P80>1,"substrate-heavy / mass-light","balanced")) | Z80: =IF(F80="","",H80-IFERROR(VLOOKUP(A80, Observed_Lookup!A:G, 7, FALSE),"")) | AA80: =IF(Z80="","",Z80*931.49410242) | AB80: =8*(A80+IF(F80="",D80,G80))-17*(A80+IF(F80="",D80,G80))^(2/3)-(3/4)*A80*(A80-1)/(A80+IF(F80="",D80,G80))^(1/3)-22*(IF(F80="",D80,G80)-A80)^2/(A80+IF(F80="",D80,G80))+7*IF(AND(MOD(A80,2)=0,MOD(IF(F80="",D80,G80),2)=0),1,IF(AND(MOD(A80,2)=1,MOD(IF(F80="",D80,G80),2)=1),-1,0))/SQRT((A80+IF(F80="",D80,G80)))-(25/4)*IF(AND((A80/GCD(A80,IF(F80="",D80,G80)))=1,(IF(F80="",D80,G80)/GCD(A80,IF(F80="",D80,G80)))=1),0,1) | AC80: =IF(AA80="","",AA80-AB80) | AD80: =IF(AND(A80<=83,A80<>43,A80<>61),"clock-stable","clock-boundary") | AE80: engine_matches_observed
A81: 80 | B81: Hg | C81: Mercury | D81: =A81 + INT(A81 * INT((A81-1)/12) / 12) | E81: =A81+D81 | F81: =VLOOKUP(A81, Observed_Lookup!A:G, 4, FALSE) | G81: =VLOOKUP(A81, Observed_Lookup!A:G, 5, FALSE) | H81: =VLOOKUP(A81, Observed_Lookup!A:G, 6, FALSE) | I81: =IF(F81="","",D81-G81) | J81: =IF(F81="","",E81-H81) | K81: =GCD(A81,D81) | L81: =A81/K81 | M81: =D81/K81 | N81: ="("&L81&","&M81&")" | O81: =(D81-A81)/E81 | P81: =V81/W81 | Q81: =A81 | R81: =D81 | S81: =A81 | T81: =2*A81+D81 | U81: =A81+2*D81 | V81: =8*(A81*(7117/768)+(D81-A81)*(1/64)) | W81: =4*E81*(7117/768) | X81: =W81-V81 | Y81: =IF(P81<1,"substrate-light / mass-heavy",IF(P81>1,"substrate-heavy / mass-light","balanced")) | Z81: =IF(F81="","",H81-IFERROR(VLOOKUP(A81, Observed_Lookup!A:G, 7, FALSE),"")) | AA81: =IF(Z81="","",Z81*931.49410242) | AB81: =8*(A81+IF(F81="",D81,G81))-17*(A81+IF(F81="",D81,G81))^(2/3)-(3/4)*A81*(A81-1)/(A81+IF(F81="",D81,G81))^(1/3)-22*(IF(F81="",D81,G81)-A81)^2/(A81+IF(F81="",D81,G81))+7*IF(AND(MOD(A81,2)=0,MOD(IF(F81="",D81,G81),2)=0),1,IF(AND(MOD(A81,2)=1,MOD(IF(F81="",D81,G81),2)=1),-1,0))/SQRT((A81+IF(F81="",D81,G81)))-(25/4)*IF(AND((A81/GCD(A81,IF(F81="",D81,G81)))=1,(IF(F81="",D81,G81)/GCD(A81,IF(F81="",D81,G81)))=1),0,1) | AC81: =IF(AA81="","",AA81-AB81) | AD81: =IF(AND(A81<=83,A81<>43,A81<>61),"clock-stable","clock-boundary") | AE81: engine_diff_from_observed | AF81: engine anchor Hg-206 differs from observed most-abundant Hg-202
A82: 81 | B82: Tl | C82: Thallium | D82: =A82 + INT(A82 * INT((A82-1)/12) / 12) | E82: =A82+D82 | F82: =VLOOKUP(A82, Observed_Lookup!A:G, 4, FALSE) | G82: =VLOOKUP(A82, Observed_Lookup!A:G, 5, FALSE) | H82: =VLOOKUP(A82, Observed_Lookup!A:G, 6, FALSE) | I82: =IF(F82="","",D82-G82) | J82: =IF(F82="","",E82-H82) | K82: =GCD(A82,D82) | L82: =A82/K82 | M82: =D82/K82 | N82: ="("&L82&","&M82&")" | O82: =(D82-A82)/E82 | P82: =V82/W82 | Q82: =A82 | R82: =D82 | S82: =A82 | T82: =2*A82+D82 | U82: =A82+2*D82 | V82: =8*(A82*(7117/768)+(D82-A82)*(1/64)) | W82: =4*E82*(7117/768) | X82: =W82-V82 | Y82: =IF(P82<1,"substrate-light / mass-heavy",IF(P82>1,"substrate-heavy / mass-light","balanced")) | Z82: =IF(F82="","",H82-IFERROR(VLOOKUP(A82, Observed_Lookup!A:G, 7, FALSE),"")) | AA82: =IF(Z82="","",Z82*931.49410242) | AB82: =8*(A82+IF(F82="",D82,G82))-17*(A82+IF(F82="",D82,G82))^(2/3)-(3/4)*A82*(A82-1)/(A82+IF(F82="",D82,G82))^(1/3)-22*(IF(F82="",D82,G82)-A82)^2/(A82+IF(F82="",D82,G82))+7*IF(AND(MOD(A82,2)=0,MOD(IF(F82="",D82,G82),2)=0),1,IF(AND(MOD(A82,2)=1,MOD(IF(F82="",D82,G82),2)=1),-1,0))/SQRT((A82+IF(F82="",D82,G82)))-(25/4)*IF(AND((A82/GCD(A82,IF(F82="",D82,G82)))=1,(IF(F82="",D82,G82)/GCD(A82,IF(F82="",D82,G82)))=1),0,1) | AC82: =IF(AA82="","",AA82-AB82) | AD82: =IF(AND(A82<=83,A82<>43,A82<>61),"clock-stable","clock-boundary") | AE82: engine_diff_from_observed | AF82: engine anchor Tl-216 differs from observed most-abundant Tl-205
A83: 82 | B83: Pb | C83: Lead | D83: =A83 + INT(A83 * INT((A83-1)/12) / 12) | E83: =A83+D83 | F83: =VLOOKUP(A83, Observed_Lookup!A:G, 4, FALSE) | G83: =VLOOKUP(A83, Observed_Lookup!A:G, 5, FALSE) | H83: =VLOOKUP(A83, Observed_Lookup!A:G, 6, FALSE) | I83: =IF(F83="","",D83-G83) | J83: =IF(F83="","",E83-H83) | K83: =GCD(A83,D83) | L83: =A83/K83 | M83: =D83/K83 | N83: ="("&L83&","&M83&")" | O83: =(D83-A83)/E83 | P83: =V83/W83 | Q83: =A83 | R83: =D83 | S83: =A83 | T83: =2*A83+D83 | U83: =A83+2*D83 | V83: =8*(A83*(7117/768)+(D83-A83)*(1/64)) | W83: =4*E83*(7117/768) | X83: =W83-V83 | Y83: =IF(P83<1,"substrate-light / mass-heavy",IF(P83>1,"substrate-heavy / mass-light","balanced")) | Z83: =IF(F83="","",H83-IFERROR(VLOOKUP(A83, Observed_Lookup!A:G, 7, FALSE),"")) | AA83: =IF(Z83="","",Z83*931.49410242) | AB83: =8*(A83+IF(F83="",D83,G83))-17*(A83+IF(F83="",D83,G83))^(2/3)-(3/4)*A83*(A83-1)/(A83+IF(F83="",D83,G83))^(1/3)-22*(IF(F83="",D83,G83)-A83)^2/(A83+IF(F83="",D83,G83))+7*IF(AND(MOD(A83,2)=0,MOD(IF(F83="",D83,G83),2)=0),1,IF(AND(MOD(A83,2)=1,MOD(IF(F83="",D83,G83),2)=1),-1,0))/SQRT((A83+IF(F83="",D83,G83)))-(25/4)*IF(AND((A83/GCD(A83,IF(F83="",D83,G83)))=1,(IF(F83="",D83,G83)/GCD(A83,IF(F83="",D83,G83)))=1),0,1) | AC83: =IF(AA83="","",AA83-AB83) | AD83: =IF(AND(A83<=83,A83<>43,A83<>61),"clock-stable","clock-boundary") | AE83: engine_diff_from_observed | AF83: engine anchor Pb-225 differs from observed most-abundant Pb-208
A84: 83 | B84: Bi | C84: Bismuth | D84: =A84 + INT(A84 * INT((A84-1)/12) / 12) | E84: =A84+D84 | F84: =VLOOKUP(A84, Observed_Lookup!A:G, 4, FALSE) | G84: =VLOOKUP(A84, Observed_Lookup!A:G, 5, FALSE) | H84: =VLOOKUP(A84, Observed_Lookup!A:G, 6, FALSE) | I84: =IF(F84="","",D84-G84) | J84: =IF(F84="","",E84-H84) | K84: =GCD(A84,D84) | L84: =A84/K84 | M84: =D84/K84 | N84: ="("&L84&","&M84&")" | O84: =(D84-A84)/E84 | P84: =V84/W84 | Q84: =A84 | R84: =D84 | S84: =A84 | T84: =2*A84+D84 | U84: =A84+2*D84 | V84: =8*(A84*(7117/768)+(D84-A84)*(1/64)) | W84: =4*E84*(7117/768) | X84: =W84-V84 | Y84: =IF(P84<1,"substrate-light / mass-heavy",IF(P84>1,"substrate-heavy / mass-light","balanced")) | Z84: =IF(F84="","",H84-IFERROR(VLOOKUP(A84, Observed_Lookup!A:G, 7, FALSE),"")) | AA84: =IF(Z84="","",Z84*931.49410242) | AB84: =8*(A84+IF(F84="",D84,G84))-17*(A84+IF(F84="",D84,G84))^(2/3)-(3/4)*A84*(A84-1)/(A84+IF(F84="",D84,G84))^(1/3)-22*(IF(F84="",D84,G84)-A84)^2/(A84+IF(F84="",D84,G84))+7*IF(AND(MOD(A84,2)=0,MOD(IF(F84="",D84,G84),2)=0),1,IF(AND(MOD(A84,2)=1,MOD(IF(F84="",D84,G84),2)=1),-1,0))/SQRT((A84+IF(F84="",D84,G84)))-(25/4)*IF(AND((A84/GCD(A84,IF(F84="",D84,G84)))=1,(IF(F84="",D84,G84)/GCD(A84,IF(F84="",D84,G84)))=1),0,1) | AC84: =IF(AA84="","",AA84-AB84) | AD84: =IF(AND(A84<=83,A84<>43,A84<>61),"clock-stable","clock-boundary") | AE84: engine_diff_from_observed | AF84: engine anchor Bi-235 differs from observed most-abundant Bi-209
A85: 84 | B85: Po | C85: Polonium | D85: =A85 + INT(A85 * INT((A85-1)/12) / 12) | E85: =A85+D85 | F85: =VLOOKUP(A85, Observed_Lookup!A:G, 4, FALSE) | G85: =VLOOKUP(A85, Observed_Lookup!A:G, 5, FALSE) | H85: =VLOOKUP(A85, Observed_Lookup!A:G, 6, FALSE) | I85: =IF(F85="","",D85-G85) | J85: =IF(F85="","",E85-H85) | K85: =GCD(A85,D85) | L85: =A85/K85 | M85: =D85/K85 | N85: ="("&L85&","&M85&")" | O85: =(D85-A85)/E85 | P85: =V85/W85 | Q85: =A85 | R85: =D85 | S85: =A85 | T85: =2*A85+D85 | U85: =A85+2*D85 | V85: =8*(A85*(7117/768)+(D85-A85)*(1/64)) | W85: =4*E85*(7117/768) | X85: =W85-V85 | Y85: =IF(P85<1,"substrate-light / mass-heavy",IF(P85>1,"substrate-heavy / mass-light","balanced")) | Z85: =IF(F85="","",H85-IFERROR(VLOOKUP(A85, Observed_Lookup!A:G, 7, FALSE),"")) | AA85: =IF(Z85="","",Z85*931.49410242) | AB85: =8*(A85+IF(F85="",D85,G85))-17*(A85+IF(F85="",D85,G85))^(2/3)-(3/4)*A85*(A85-1)/(A85+IF(F85="",D85,G85))^(1/3)-22*(IF(F85="",D85,G85)-A85)^2/(A85+IF(F85="",D85,G85))+7*IF(AND(MOD(A85,2)=0,MOD(IF(F85="",D85,G85),2)=0),1,IF(AND(MOD(A85,2)=1,MOD(IF(F85="",D85,G85),2)=1),-1,0))/SQRT((A85+IF(F85="",D85,G85)))-(25/4)*IF(AND((A85/GCD(A85,IF(F85="",D85,G85)))=1,(IF(F85="",D85,G85)/GCD(A85,IF(F85="",D85,G85)))=1),0,1) | AC85: =IF(AA85="","",AA85-AB85) | AD85: =IF(AND(A85<=83,A85<>43,A85<>61),"clock-stable","clock-boundary") | AE85: engine_diff_from_observed | AF85: engine anchor Po-245 differs from observed most-abundant Po-209
A86: 85 | B86: At | C86: Astatine | D86: =A86 + INT(A86 * INT((A86-1)/12) / 12) | E86: =A86+D86 | F86: =VLOOKUP(A86, Observed_Lookup!A:G, 4, FALSE) | G86: =VLOOKUP(A86, Observed_Lookup!A:G, 5, FALSE) | H86: =VLOOKUP(A86, Observed_Lookup!A:G, 6, FALSE) | I86: =IF(F86="","",D86-G86) | J86: =IF(F86="","",E86-H86) | K86: =GCD(A86,D86) | L86: =A86/K86 | M86: =D86/K86 | N86: ="("&L86&","&M86&")" | O86: =(D86-A86)/E86 | P86: =V86/W86 | Q86: =A86 | R86: =D86 | S86: =A86 | T86: =2*A86+D86 | U86: =A86+2*D86 | V86: =8*(A86*(7117/768)+(D86-A86)*(1/64)) | W86: =4*E86*(7117/768) | X86: =W86-V86 | Y86: =IF(P86<1,"substrate-light / mass-heavy",IF(P86>1,"substrate-heavy / mass-light","balanced")) | Z86: =IF(F86="","",H86-IFERROR(VLOOKUP(A86, Observed_Lookup!A:G, 7, FALSE),"")) | AA86: =IF(Z86="","",Z86*931.49410242) | AB86: =8*(A86+IF(F86="",D86,G86))-17*(A86+IF(F86="",D86,G86))^(2/3)-(3/4)*A86*(A86-1)/(A86+IF(F86="",D86,G86))^(1/3)-22*(IF(F86="",D86,G86)-A86)^2/(A86+IF(F86="",D86,G86))+7*IF(AND(MOD(A86,2)=0,MOD(IF(F86="",D86,G86),2)=0),1,IF(AND(MOD(A86,2)=1,MOD(IF(F86="",D86,G86),2)=1),-1,0))/SQRT((A86+IF(F86="",D86,G86)))-(25/4)*IF(AND((A86/GCD(A86,IF(F86="",D86,G86)))=1,(IF(F86="",D86,G86)/GCD(A86,IF(F86="",D86,G86)))=1),0,1) | AC86: =IF(AA86="","",AA86-AB86) | AD86: =IF(AND(A86<=83,A86<>43,A86<>61),"clock-stable","clock-boundary") | AE86: engine_diff_from_observed | AF86: engine anchor At-170 differs from observed most-abundant At-210
...

Sheet Constants
A1: name | B1: value | C1: meaning
A2: R | B2: 12 | C2: radix (substrate route shape)
A3: D | B3: 3 | C3: substrate dimension
A4: S | B4: 8 | C4: split inventory shape (octet)
A5: alpha_H | B5: 2 | C5: partition algebra generator
A6: Theta | B6: 18 | C6: overlap shape (alpha_H * D^2)
A7: F | B7: 81 | C7: face shape (D^4)
A8: M | B8: 126 | C8: retained matter-support shape
A9: L | B9: 162 | C9: closed carrier ledger
A10: kappa_num | B10: 7117 | C10: kappa numerator (7117/768)
A11: kappa_den | B11: 768 | C11: kappa denominator
A12: g_num | B12: 1 | C12: g numerator (1/64)
A13: g_den | B13: 64 | C13: g denominator
... A16: U_TO_MEV | B16: 931.4941 | C16: CODATA atomic mass unit in MeV

Sheet Observed_Lookup
A1: Z | B1: symbol | C1: name | D1: observed_isotope | E1: N_observed | F1: A_observed | G1: m_obs_u
A2: 1 | B2: H | C2: Hydrogen | D2: H-1 | E2: 0 | F2: 1 | G2: 1.007825
A3: 2 | B3: He | C3: Helium | D3: He-4 | E3: 2 | F3: 4 | G3: 4.0026033
A4: 3 | B4: Li | C4: Lithium | D4: Li-7 | E4: 4 | F4: 7 | G4: 7.0160034
A5: 4 | B5: Be | C5: Beryllium | D5: Be-9 | E5: 5 | F5: 9 | G5: 9.0121831
A6: 5 | B6: B | C6: Boron | D6: B-11 | E6: 6 | F6: 11 | G6: 11.009305
A7: 6 | B7: C | C7: Carbon | D7: C-12 | E7: 6 | F7: 12 | G7: 12
A8: 7 | B8: N | C8: Nitrogen | D8: N-14 | E8: 7 | F8: 14 | G8: 14.003074
A9: 8 | B9: O | C9: Oxygen | D9: O-16 | E9: 8 | F9: 16 | G9: 15.994915
A10: 9 | B10: F | C10: Fluorine | D10: F-19 | E10: 10 | F10: 19 | G10: 18.998403
A11: 10 | B11: Ne | C11: Neon | D11: Ne-20 | E11: 10 | F11: 20 | G11: 19.99244
A12: 11 | B12: Na | C12: Sodium | D12: Na-23 | E12: 12 | F12: 23 | G12: 22.989769
A13: 12 | B13: Mg | C13: Magnesium | D13: Mg-24 | E13: 12 | F13: 24 | G13: 23.985042
... A119: 118 | B119: Og | C119: Oganesson | D119: Og-294 | E119: 176 | F119: 294 | G119: 294.21392
A120: 119 | B120: Uue | C120: Ununennium
A121: 120 | B121: Ubn | C121: Unbinilium
A122: 121 | B122: Ubu | C122: Unbiunium
A123: 122 | B123: Ubb | C123: Unbibium
A124: 123 | B124: Ubt | C124: Unbitrium
A125: 124 | B125: Ubq | C125: Unbiquadium
A126: 125 | B126: Ubp | C126: Unbipentium
A127: 126 | B127: Ubh | C127: Unbihexium
